Workbook

Sheet Инструкция
B2: Модель TCO (Total Cost of Ownership) — кейс «Africa Delivery», горизонт 5 лет
B4: Зачем этот файл
B5: Задача | C5: Оценить полную стоимость владения выбранным архитектурным вариантом на 5 лет и использовать цифры как аргумент в ADR №1 («Выбор архитектурного стиля»).
B6: Как использовать | C6: Заполни один и тот же шаблон для каждого рассматриваемого варианта (например: модульный монолит / SOA / микросервисы) — сравнивать нужно итоги, а не ощущения.
B8: Цветовая легенда
B9: Синий текст на жёлтом фоне | C9: Ячейки для заполнения. Только их и редактируем.
B10: Чёрный текст | C10: Формулы. Не трогаем — пересчитаются сами.
B11: Зелёный текст | C11: Ссылка на лист «Допущения».
B13: Порядок работы
B14: Шаг 1 | C14: Лист «Допущения» → блок 1: вбить драйверы бизнеса по годам (активные пользователи, число заказов, средний чек). Из них считается GMV.
B15: Шаг 2 | C15: Лист «Допущения» → блок 2: финансовые допущения (инфляция, рост ФОТ, ставка дисконтирования, резерв, целевой SLO).
B16: Шаг 3 | C16: Лист «TCO» → в колонке «База, $/год (Год 1)» указать затраты первого года по каждой статье. Лишние статьи оставить пустыми, свои — дописать в свободные строки.
B17: Шаг 4 | C17: Лист «TCO» → в колонке «Драйвер роста» выбрать из выпадающего списка, от чего растёт статья: фикс / инфляция / ФОТ / пользователи / заказы / GMV. Годы 2–5 посчитаются сами.
B18: Шаг 5 | C18: Посмотреть блок «Ключевые метрики» внизу листа «TCO»: итог за 5 лет, NPV, стоимость на заказ, проверку бюджета CFO ($9k/мес на облако).
B20: Что важно не забыть в этом кейсе
B21: Бюджет CFO | C21: $9 000/мес на облако на старте. Если Год 1 в блоке «Облачная инфраструктура» не проходит — это архитектурное решение, а не ошибка модели: опиши, что урезаешь.
B22: Цена простоя | C22: Инвестор оценивает минуту простоя в $12 000. Целевой SLO 99,99% = 52,6 мин/год ≈ $631k. Этот риск считается отдельным блоком — сравни его со стоимостью резервирования.
B23: Транзакционные расходы | C23: Комиссии M-Pesa / Flutterwave / Paystack, SMS и WhatsApp растут с GMV и числом заказов и на горизонте 5 лет обычно обгоняют инфраструктуру. Не забудь их — это типичная ошибка.
B24: Сравнение вариантов | C24: Транзакционные расходы (блок 3) почти одинаковы для любой архитектуры — это pass-through от оборота. Варианты архитектуры сравнивай по блокам 1, 2, 4 и 6.
B25: Разовые затраты | C25: Комплаенс-аудит NDPR/POPIA, пентест, миграция — если статья возникает не каждый год, просто перезапиши формулу в нужной ячейке года числом (и покрась в синий).
B26: Люди | C26: ФОТ команды — обычно самая крупная статья TCO. Микросервисы дешевле в масштабировании, но дороже в эксплуатации: это должно быть видно в цифрах, а не только в тексте ADR.
B28: Все числа в файле — примеры для демонстрации формата. Замени их своими оценками и укажи источник в колонке «Комментарий / источник».

Sheet Допущения
B2: Допущения модели TCO — Africa Delivery
B3: Заполняются только ячейки с жёлтой заливкой. Все числа ниже — пример, заменить своими.
B5: 1. Драйверы бизнеса — заполнить
B6: Показатель | C6: Год 1 | D6: Год 2 | E6: Год 3 | F6: Год 4 | G6: Год 5 | H6: Комментарий / источник
B7: Активные пользователи (на конец года) | C7: 400000 | D7: 1200000 | E7: 3000000 | F7: 6000000 | G7: 10000000 | H7: Год 1: 1M+ регистраций (цель бизнеса), активные - доля; год 5: путь к 10M (артефакт 5)
B8: Число заказов в год | C8: 200000 | D8: 1200000 | E8: 4000000 | F8: 8000000 | G8: 14000000 | H8: Год 1: пилот 2k заказов/день в пике (Task1 Q1); рост с выходом в 5 стран
B9: Средний чек (AOV), $ | C9: 18 | D9: 19 | E9: 20 | F9: 21 | G9: 22 | H9: Оценка по рынку Jumia/Takealot, low-price стратегия (описание кейса)
B10: GMV, $ в год (расчёт) | C10: =C8*C9 -> 3600000 | D10: =D8*D9 -> 22800000 | E10: =E8*E9 -> 80000000 | F10: =F8*F9 -> 168000000 | G10: =G8*G9 -> 308000000 | H10: Расчёт: заказы × средний чек
B12: 2. Финансовые допущения — заполнить
B13: Параметр | C13: Значение | H13: Комментарий / источник
B14: Инфляция затрат, % в год | C14: 0.08 | H14: Применяется к статьям с драйвером «инфляция»
B15: Рост ФОТ, % в год | C15: 0.12 | H15: Дефицит ИТ-специалистов на рынке — рост выше инфляции
B16: Ставка дисконтирования, % в год | C16: 0.2 | H16: Для расчёта NPV затрат. Стартап, высокий риск
B17: Резерв на непредвиденное (contingency), % | C17: 0.15 | H17: Надбавка к прямым затратам
B18: Бюджет CFO на облако, $/мес | C18: 5000 | H18: Жесткий потолок $5k/мес (артефакт 6)
B19: Стоимость минуты простоя, $ | C19: 12000 | H19: Оценка инвестора из условия кейса
B20: Целевой SLO (доступность), % | C20: 0.999 | H20: Дифференцированный SLO: 99,9% на контур заказа (Task1, противоречие 1)
B21: Учитывать стоимость простоя в TCO (1 — да, 0 — нет) | C21: 0 | H21: Стоимость простоя считаем отдельным сценарием в ADR-001, в TCO не включаем
B23: 3. Индексы роста — расчёт, не редактировать
B24: Драйвер | C24: Год 1 | D24: Год 2 | E24: Год 3 | F24: Год 4 | G24: Год 5 | H24: Как считается
B25: фикс | C25: 1 | D25: 1 | E25: 1 | F25: 1 | G25: 1 | H25: Затраты не меняются по годам
B26: инфляция | C26: 1 | D26: =C26*(1+$C$14) -> 1.08 | E26: =D26*(1+$C$14) -> 1.1664 | F26: =E26*(1+$C$14) -> 1.259712 | G26: =F26*(1+$C$14) -> 1.360489 | H26: Год N = Год N-1 × (1 + инфляция)
B27: ФОТ | C27: 1 | D27: =C27*(1+$C$15) -> 1.12 | E27: =D27*(1+$C$15) -> 1.2544 | F27: =E27*(1+$C$15) -> 1.404928 | G27: =F27*(1+$C$15) -> 1.5735194 | H27: Год N = Год N-1 × (1 + рост ФОТ)
B28: пользователи | C28: =C7/$C$7 -> 1 | D28: =D7/$C$7 -> 3 | E28: =E7/$C$7 -> 7.5 | F28: =F7/$C$7 -> 15 | G28: =G7/$C$7 -> 25 | H28: Пропорционально числу активных пользователей
B29: заказы | C29: =C8/$C$8 -> 1 | D29: =D8/$C$8 -> 6 | E29: =E8/$C$8 -> 20 | F29: =F8/$C$8 -> 40 | G29: =G8/$C$8 -> 70 | H29: Пропорционально числу заказов
B30: GMV | C30: =C10/$C$10 -> 1 | D30: =D10/$C$10 -> 6.3333333 | E30: =E10/$C$10 -> 22.222222 | F30: =F10/$C$10 -> 46.666667 | G30: =G10/$C$10 -> 85.555556 | H30: Пропорционально обороту
B32: Драйвер «пользователи» — упрощение: облачные расходы редко растут строго линейно (есть эффект масштаба и обратный эффект — рост нагрузки на БД). При желании введи свой драйвер отдельной строкой в таблице индексов.

Sheet TCO-A-monolit
B2: TCO на 5 лет - Africa Delivery - вариант TCO-A-monolit
B3: Заполняем колонки «Драйвер роста» и «База, $/год (Год 1)». Годы 1–5 считаются автоматически.
B5: Статья затрат | C5: Драйвер роста | D5: База, $/год (Год 1) | E5: Год 1 | F5: Год 2 | G5: Год 3 | H5: Год 4 | I5: Год 5 | J5: Итого 5 лет | K5: Доля | L5: Комментарий / источник
B6: БЛОК 1. Облачная инфраструктура (OpEx)
B7: Compute: ноды / контейнеры / serverless | C7: пользователи | D7: 6000 | E7: {=IF($D7="","",$D7*INDEX(Допущения!$C$25:$G$30,MATCH($C7,Допущения!$B$25:$B$30,0),1))} -> 6000 | F7: {=IF($D7="","",$D7*INDEX(Допущения!$C$25:$G$30,MATCH($C7,Допущения!$B$25:$B$30,0),2))} -> 18000 | G7: {=IF($D7="","",$D7*INDEX(Допущения!$C$25:$G$30,MATCH($C7,Допущения!$B$25:$B$30,0),3))} -> 45000 | H7: {=IF($D7="","",$D7*INDEX(Допущения!$C$25:$G$30,MATCH($C7,Допущения!$B$25:$B$30,0),4))} -> 90000 | I7: {=IF($D7="","",$D7*INDEX(Допущения!$C$25:$G$30,MATCH($C7,Допущения!$B$25:$B$30,0),5))} -> 150000 | J7: =SUM(E7:I7) -> 309000 | L7: 2-3 ноды монолита + автомасштаб, managed containers
B8: Управляемые БД (PostgreSQL, реплики) | C8: пользователи | D8: 4200 | E8: {=IF($D8="","",$D8*INDEX(Допущения!$C$25:$G$30,MATCH($C8,Допущения!$B$25:$B$30,0),1))} -> 4200 | F8: {=IF($D8="","",$D8*INDEX(Допущения!$C$25:$G$30,MATCH($C8,Допущения!$B$25:$B$30,0),2))} -> 12600 | G8: {=IF($D8="","",$D8*INDEX(Допущения!$C$25:$G$30,MATCH($C8,Допущения!$B$25:$B$30,0),3))} -> 31500 | H8: {=IF($D8="","",$D8*INDEX(Допущения!$C$25:$G$30,MATCH($C8,Допущения!$B$25:$B$30,0),4))} -> 63000 | I8: {=IF($D8="","",$D8*INDEX(Допущения!$C$25:$G$30,MATCH($C8,Допущения!$B$25:$B$30,0),5))} -> 105000 | J8: =SUM(E8:I8) -> 216300 | L8: Managed PostgreSQL + read replica (вкл. дашборд CEO в год 1)
B9: Хранилище объектов и резервные копии | C9: пользователи | D9: 1800 | E9: {=IF($D9="","",$D9*INDEX(Допущения!$C$25:$G$30,MATCH($C9,Допущения!$B$25:$B$30,0),1))} -> 1800 | F9: {=IF($D9="","",$D9*INDEX(Допущения!$C$25:$G$30,MATCH($C9,Допущения!$B$25:$B$30,0),2))} -> 5400 | G9: {=IF($D9="","",$D9*INDEX(Допущения!$C$25:$G$30,MATCH($C9,Допущения!$B$25:$B$30,0),3))} -> 13500 | H9: {=IF($D9="","",$D9*INDEX(Допущения!$C$25:$G$30,MATCH($C9,Допущения!$B$25:$B$30,0),4))} -> 27000 | I9: {=IF($D9="","",$D9*INDEX(Допущения!$C$25:$G$30,MATCH($C9,Допущения!$B$25:$B$30,0),5))} -> 45000 | J9: =SUM(E9:I9) -> 92700 | L9: S3-совместимое хранилище, фото 5000 SKU, бэкапы
B10: CDN и исходящий трафик | C10: пользователи | D10: 3600 | E10: {=IF($D10="","",$D10*INDEX(Допущения!$C$25:$G$30,MATCH($C10,Допущения!$B$25:$B$30,0),1))} -> 3600 | F10: {=IF($D10="","",$D10*INDEX(Допущения!$C$25:$G$30,MATCH($C10,Допущения!$B$25:$B$30,0),2))} -> 10800 | G10: {=IF($D10="","",$D10*INDEX(Допущения!$C$25:$G$30,MATCH($C10,Допущения!$B$25:$B$30,0),3))} -> 27000 | H10: {=IF($D10="","",$D10*INDEX(Допущения!$C$25:$G$30,MATCH($C10,Допущения!$B$25:$B$30,0),4))} -> 54000 | I10: {=IF($D10="","",$D10*INDEX(Допущения!$C$25:$G$30,MATCH($C10,Допущения!$B$25:$B$30,0),5))} -> 90000 | J10: =SUM(E10:I10) -> 185400 | L10: CDN, картинки WebP, мобильный трафик 3G/4G
B11: Очереди / стриминг (Kafka, SQS) | C11: пользователи | D11: 1200 | E11: {=IF($D11="","",$D11*INDEX(Допущения!$C$25:$G$30,MATCH($C11,Допущения!$B$25:$B$30,0),1))} -> 1200 | F11: {=IF($D11="","",$D11*INDEX(Допущения!$C$25:$G$30,MATCH($C11,Допущения!$B$25:$B$30,0),2))} -> 3600 | G11: {=IF($D11="","",$D11*INDEX(Допущения!$C$25:$G$30,MATCH($C11,Допущения!$B$25:$B$30,0),3))} -> 9000 | H11: {=IF($D11="","",$D11*INDEX(Допущения!$C$25:$G$30,MATCH($C11,Допущения!$B$25:$B$30,0),4))} -> 18000 | I11: {=IF($D11="","",$D11*INDEX(Допущения!$C$25:$G$30,MATCH($C11,Допущения!$B$25:$B$30,0),5))} -> 30000 | J11: =SUM(E11:I11) -> 61800 | L11: Managed очередь (SQS/Pub/Sub), без self-hosted Kafka
B12: Резервный регион / DR | C12: пользователи | D12: 3000 | E12: {=IF($D12="","",$D12*INDEX(Допущения!$C$25:$G$30,MATCH($C12,Допущения!$B$25:$B$30,0),1))} -> 3000 | F12: {=IF($D12="","",$D12*INDEX(Допущения!$C$25:$G$30,MATCH($C12,Допущения!$B$25:$B$30,0),2))} -> 9000 | G12: {=IF($D12="","",$D12*INDEX(Допущения!$C$25:$G$30,MATCH($C12,Допущения!$B$25:$B$30,0),3))} -> 22500 | H12: {=IF($D12="","",$D12*INDEX(Допущения!$C$25:$G$30,MATCH($C12,Допущения!$B$25:$B$30,0),4))} -> 45000 | I12: {=IF($D12="","",$D12*INDEX(Допущения!$C$25:$G$30,MATCH($C12,Допущения!$B$25:$B$30,0),5))} -> 75000 | J12: =SUM(E12:I12) -> 154500 | L12: Кросс-AZ реплика БД (RPO 0 внутри региона), бэкапы в af-south-1
B13: Локальное размещение данных (NDPR, Нигерия) | C13: инфляция | D13: 9600 | E13: {=IF($D13="","",$D13*INDEX(Допущения!$C$25:$G$30,MATCH($C13,Допущения!$B$25:$B$30,0),1))} -> 9600 | F13: {=IF($D13="","",$D13*INDEX(Допущения!$C$25:$G$30,MATCH($C13,Допущения!$B$25:$B$30,0),2))} -> 10368 | G13: {=IF($D13="","",$D13*INDEX(Допущения!$C$25:$G$30,MATCH($C13,Допущения!$B$25:$B$30,0),3))} -> 11197.44 | H13: {=IF($D13="","",$D13*INDEX(Допущения!$C$25:$G$30,MATCH($C13,Допущения!$B$25:$B$30,0),4))} -> 12093.235 | I13: {=IF($D13="","",$D13*INDEX(Допущения!$C$25:$G$30,MATCH($C13,Допущения!$B$25:$B$30,0),5))} -> 13060.694 | J13: =SUM(E13:I13) -> 56319.369 | L13: Локальный провайдер в Нигерии под ПДн (артефакт 3, ADR-003)
B14: Аналитическая реплика / витрина (OLAP) | C14: пользователи | D14: 2400 | E14: 0 | F14: {=IF($D14="","",$D14*INDEX(Допущения!$C$25:$G$30,MATCH($C14,Допущения!$B$25:$B$30,0),2))} -> 7200 | G14: {=IF($D14="","",$D14*INDEX(Допущения!$C$25:$G$30,MATCH($C14,Допущения!$B$25:$B$30,0),3))} -> 18000 | H14: {=IF($D14="","",$D14*INDEX(Допущения!$C$25:$G$30,MATCH($C14,Допущения!$B$25:$B$30,0),4))} -> 36000 | I14: {=IF($D14="","",$D14*INDEX(Допущения!$C$25:$G$30,MATCH($C14,Допущения!$B$25:$B$30,0),5))} -> 60000 | J14: =SUM(E14:I14) -> 121200 | L14: Аналитическая реплика/витрина OLAP(ЛК продавца, B2B-отчеты) со второго года
B15: Итого по блоку | E15: =SUM(E7:E14) -> 29400 | F15: =SUM(F7:F14) -> 76968 | G15: =SUM(G7:G14) -> 177697.44 | H15: =SUM(H7:H14) -> 345093.24 | I15: =SUM(I7:I14) -> 568060.69 | J15: =SUM(J7:J14) -> 1197219.4 | K15: =IFERROR(J15/$J$51,0) -> 0.027252714
B17: БЛОК 2. Лицензии, SaaS и инструменты
B18: Observability (метрики, логи, трейсинг) | C18: пользователи | D18: 2400 | E18: {=IF($D18="","",$D18*INDEX(Допущения!$C$25:$G$30,MATCH($C18,Допущения!$B$25:$B$30,0),1))} -> 2400 | F18: {=IF($D18="","",$D18*INDEX(Допущения!$C$25:$G$30,MATCH($C18,Допущения!$B$25:$B$30,0),2))} -> 7200 | G18: {=IF($D18="","",$D18*INDEX(Допущения!$C$25:$G$30,MATCH($C18,Допущения!$B$25:$B$30,0),3))} -> 18000 | H18: {=IF($D18="","",$D18*INDEX(Допущения!$C$25:$G$30,MATCH($C18,Допущения!$B$25:$B$30,0),4))} -> 36000 | I18: {=IF($D18="","",$D18*INDEX(Допущения!$C$25:$G$30,MATCH($C18,Допущения!$B$25:$B$30,0),5))} -> 60000 | J18: =SUM(E18:I18) -> 123600 | L18: Grafana Cloud free tier + self-hosted OSS стек
B19: CI/CD, репозиторий, артефакты | C19: инфляция | D19: 2400 | E19: {=IF($D19="","",$D19*INDEX(Допущения!$C$25:$G$30,MATCH($C19,Допущения!$B$25:$B$30,0),1))} -> 2400 | F19: {=IF($D19="","",$D19*INDEX(Допущения!$C$25:$G$30,MATCH($C19,Допущения!$B$25:$B$30,0),2))} -> 2592 | G19: {=IF($D19="","",$D19*INDEX(Допущения!$C$25:$G$30,MATCH($C19,Допущения!$B$25:$B$30,0),3))} -> 2799.36 | H19: {=IF($D19="","",$D19*INDEX(Допущения!$C$25:$G$30,MATCH($C19,Допущения!$B$25:$B$30,0),4))} -> 3023.3088 | I19: {=IF($D19="","",$D19*INDEX(Допущения!$C$25:$G$30,MATCH($C19,Допущения!$B$25:$B$30,0),5))} -> 3265.1735 | J19: =SUM(E19:I19) -> 14079.842 | L19: GitHub Team на 8-10 человек
B20: Безопасность: WAF, секреты, антифрод | C20: пользователи | D20: 3600 | E20: {=IF($D20="","",$D20*INDEX(Допущения!$C$25:$G$30,MATCH($C20,Допущения!$B$25:$B$30,0),1))} -> 3600 | F20: {=IF($D20="","",$D20*INDEX(Допущения!$C$25:$G$30,MATCH($C20,Допущения!$B$25:$B$30,0),2))} -> 10800 | G20: {=IF($D20="","",$D20*INDEX(Допущения!$C$25:$G$30,MATCH($C20,Допущения!$B$25:$B$30,0),3))} -> 27000 | H20: {=IF($D20="","",$D20*INDEX(Допущения!$C$25:$G$30,MATCH($C20,Допущения!$B$25:$B$30,0),4))} -> 54000 | I20: {=IF($D20="","",$D20*INDEX(Допущения!$C$25:$G$30,MATCH($C20,Допущения!$B$25:$B$30,0),5))} -> 90000 | J20: =SUM(E20:I20) -> 185400 | L20: Cloud WAF + секреты; антифрод - правила в монолите
B21: WhatsApp Business API (подписка) | C21: инфляция | D21: 3000 | E21: {=IF($D21="","",$D21*INDEX(Допущения!$C$25:$G$30,MATCH($C21,Допущения!$B$25:$B$30,0),1))} -> 3000 | F21: {=IF($D21="","",$D21*INDEX(Допущения!$C$25:$G$30,MATCH($C21,Допущения!$B$25:$B$30,0),2))} -> 3240 | G21: {=IF($D21="","",$D21*INDEX(Допущения!$C$25:$G$30,MATCH($C21,Допущения!$B$25:$B$30,0),3))} -> 3499.2 | H21: {=IF($D21="","",$D21*INDEX(Допущения!$C$25:$G$30,MATCH($C21,Допущения!$B$25:$B$30,0),4))} -> 3779.136 | I21: {=IF($D21="","",$D21*INDEX(Допущения!$C$25:$G$30,MATCH($C21,Допущения!$B$25:$B$30,0),5))} -> 4081.4669 | J21: =SUM(E21:I21) -> 17599.803 | L21: WhatsApp Business API подписка
B22: Прочее ПО и подписки | C22: инфляция | D22: 2400 | E22: {=IF($D22="","",$D22*INDEX(Допущения!$C$25:$G$30,MATCH($C22,Допущения!$B$25:$B$30,0),1))} -> 2400 | F22: {=IF($D22="","",$D22*INDEX(Допущения!$C$25:$G$30,MATCH($C22,Допущения!$B$25:$B$30,0),2))} -> 2592 | G22: {=IF($D22="","",$D22*INDEX(Допущения!$C$25:$G$30,MATCH($C22,Допущения!$B$25:$B$30,0),3))} -> 2799.36 | H22: {=IF($D22="","",$D22*INDEX(Допущения!$C$25:$G$30,MATCH($C22,Допущения!$B$25:$B$30,0),4))} -> 3023.3088 | I22: {=IF($D22="","",$D22*INDEX(Допущения!$C$25:$G$30,MATCH($C22,Допущения!$B$25:$B$30,0),5))} -> 3265.1735 | J22: =SUM(E22:I22) -> 14079.842 | L22: Таск-трекер, дизайн, аналитика
C23: фикс | E23: {=IF($D23="","",$D23*INDEX(Допущения!$C$25:$G$30,MATCH($C23,Допущения!$B$25:$B$30,0),1))} | F23: {=IF($D23="","",$D23*INDEX(Допущения!$C$25:$G$30,MATCH($C23,Допущения!$B$25:$B$30,0),2))} | G23: {=IF($D23="","",$D23*INDEX(Допущения!$C$25:$G$30,MATCH($C23,Допущения!$B$25:$B$30,0),3))} | H23: {=IF($D23="","",$D23*INDEX(Допущения!$C$25:$G$30,MATCH($C23,Допущения!$B$25:$B$30,0),4))} | I23: {=IF($D23="","",$D23*INDEX(Допущения!$C$25:$G$30,MATCH($C23,Допущения!$B$25:$B$30,0),5))} | J23: =SUM(E23:I23) -> 0 | L23: Своя статья
B24: Итого по блоку | E24: =SUM(E18:E23) -> 13800 | F24: =SUM(F18:F23) -> 26424 | G24: =SUM(G18:G23) -> 54097.92 | H24: =SUM(H18:H23) -> 99825.754 | I24: =SUM(I18:I23) -> 160611.81 | J24: =SUM(J18:J23) -> 354759.49 | K24: =IFERROR(J24/$J$51,0) -> 0.0080755115
B26: БЛОК 3. Транзакционные расходы (Buy / Partner)
B27: Комиссии платёжных провайдеров | C27: GMV | D27: 100800 | E27: {=IF($D27="","",$D27*INDEX(Допущения!$C$25:$G$30,MATCH($C27,Допущения!$B$25:$B$30,0),1))} -> 100800 | F27: {=IF($D27="","",$D27*INDEX(Допущения!$C$25:$G$30,MATCH($C27,Допущения!$B$25:$B$30,0),2))} -> 638400 | G27: {=IF($D27="","",$D27*INDEX(Допущения!$C$25:$G$30,MATCH($C27,Допущения!$B$25:$B$30,0),3))} -> 2240000 | H27: {=IF($D27="","",$D27*INDEX(Допущения!$C$25:$G$30,MATCH($C27,Допущения!$B$25:$B$30,0),4))} -> 4704000 | I27: {=IF($D27="","",$D27*INDEX(Допущения!$C$25:$G$30,MATCH($C27,Допущения!$B$25:$B$30,0),5))} -> 8624000 | J27: =SUM(E27:I27) -> 16307200 | L27: комиссия ~2,2%
B28: SMS-уведомления | C28: заказы | D28: 16000 | E28: {=IF($D28="","",$D28*INDEX(Допущения!$C$25:$G$30,MATCH($C28,Допущения!$B$25:$B$30,0),1))} -> 16000 | F28: {=IF($D28="","",$D28*INDEX(Допущения!$C$25:$G$30,MATCH($C28,Допущения!$B$25:$B$30,0),2))} -> 96000 | G28: {=IF($D28="","",$D28*INDEX(Допущения!$C$25:$G$30,MATCH($C28,Допущения!$B$25:$B$30,0),3))} -> 320000 | H28: {=IF($D28="","",$D28*INDEX(Допущения!$C$25:$G$30,MATCH($C28,Допущения!$B$25:$B$30,0),4))} -> 640000 | I28: {=IF($D28="","",$D28*INDEX(Допущения!$C$25:$G$30,MATCH($C28,Допущения!$B$25:$B$30,0),5))} -> 1120000 | J28: =SUM(E28:I28) -> 2192000 | L28: $0,04 x 2 смс на заказ (заказ + доставка)
B29: WhatsApp-сообщения (за диалог) | C29: заказы | D29: 6000 | E29: {=IF($D29="","",$D29*INDEX(Допущения!$C$25:$G$30,MATCH($C29,Допущения!$B$25:$B$30,0),1))} -> 6000 | F29: {=IF($D29="","",$D29*INDEX(Допущения!$C$25:$G$30,MATCH($C29,Допущения!$B$25:$B$30,0),2))} -> 36000 | G29: {=IF($D29="","",$D29*INDEX(Допущения!$C$25:$G$30,MATCH($C29,Допущения!$B$25:$B$30,0),3))} -> 120000 | H29: {=IF($D29="","",$D29*INDEX(Допущения!$C$25:$G$30,MATCH($C29,Допущения!$B$25:$B$30,0),4))} -> 240000 | I29: {=IF($D29="","",$D29*INDEX(Допущения!$C$25:$G$30,MATCH($C29,Допущения!$B$25:$B$30,0),5))} -> 420000 | J29: =SUM(E29:I29) -> 822000 | L29: WhatsApp conversations для части заказов
B30: Логистика: интеграции и комиссии партнёров | C30: заказы | D30: 100000 | E30: {=IF($D30="","",$D30*INDEX(Допущения!$C$25:$G$30,MATCH($C30,Допущения!$B$25:$B$30,0),1))} -> 100000 | F30: {=IF($D30="","",$D30*INDEX(Допущения!$C$25:$G$30,MATCH($C30,Допущения!$B$25:$B$30,0),2))} -> 600000 | G30: {=IF($D30="","",$D30*INDEX(Допущения!$C$25:$G$30,MATCH($C30,Допущения!$B$25:$B$30,0),3))} -> 2000000 | H30: {=IF($D30="","",$D30*INDEX(Допущения!$C$25:$G$30,MATCH($C30,Допущения!$B$25:$B$30,0),4))} -> 4000000 | I30: {=IF($D30="","",$D30*INDEX(Допущения!$C$25:$G$30,MATCH($C30,Допущения!$B$25:$B$30,0),5))} -> 7000000 | J30: =SUM(E30:I30) -> 13700000 | L30: $0,5/заказ комиссии Sendbox/Sendy за API и интеграции
C31: фикс | E31: {=IF($D31="","",$D31*INDEX(Допущения!$C$25:$G$30,MATCH($C31,Допущения!$B$25:$B$30,0),1))} | F31: {=IF($D31="","",$D31*INDEX(Допущения!$C$25:$G$30,MATCH($C31,Допущения!$B$25:$B$30,0),2))} | G31: {=IF($D31="","",$D31*INDEX(Допущения!$C$25:$G$30,MATCH($C31,Допущения!$B$25:$B$30,0),3))} | H31: {=IF($D31="","",$D31*INDEX(Допущения!$C$25:$G$30,MATCH($C31,Допущения!$B$25:$B$30,0),4))} | I31: {=IF($D31="","",$D31*INDEX(Допущения!$C$25:$G$30,MATCH($C31,Допущения!$B$25:$B$30,0),5))} | J31: =SUM(E31:I31) -> 0 | L31: Своя статья
B32: Итого по блоку | E32: =SUM(E27:E31) -> 222800 | F32: =SUM(F27:F31) -> 1370400 | G32: =SUM(G27:G31) -> 4680000 | H32: =SUM(H27:H31) -> 9584000 | I32: =SUM(I27:I31) -> 17164000 | J32: =SUM(J27:J31) -> 33021200 | K32: =IFERROR(J32/$J$51,0) -> 0.75167287
B34: БЛОК 4. Команда (ФОТ)
B35: Разработка (FTE × годовая ставка) | C35: ФОТ | D35: 360000 | E35: {=IF($D35="","",$D35*INDEX(Допущения!$C$25:$G$30,MATCH($C35,Допущения!$B$25:$B$30,0),1))} -> 360000 | F35: {=IF($D35="","",$D35*INDEX(Допущения!$C$25:$G$30,MATCH($C35,Допущения!$B$25:$B$30,0),2))} -> 403200 | G35: {=IF($D35="","",$D35*INDEX(Допущения!$C$25:$G$30,MATCH($C35,Допущения!$B$25:$B$30,0),3))} -> 451584 | H35: {=IF($D35="","",$D35*INDEX(Допущения!$C$25:$G$30,MATCH($C35,Допущения!$B$25:$B$30,0),4))} -> 505774.08 | I35: {=IF($D35="","",$D35*INDEX(Допущения!$C$25:$G$30,MATCH($C35,Допущения!$B$25:$B$30,0),5))} -> 566466.97 | J35: =SUM(E35:I35) -> 2287025 | L35: 6 контракторов x $60k (артефакт 6: наем заморожен)
B36: DevOps / SRE | C36: ФОТ | D36: 36000 | E36: {=IF($D36="","",$D36*INDEX(Допущения!$C$25:$G$30,MATCH($C36,Допущения!$B$25:$B$30,0),1))} -> 36000 | F36: {=IF($D36="","",$D36*INDEX(Допущения!$C$25:$G$30,MATCH($C36,Допущения!$B$25:$B$30,0),2))} -> 40320 | G36: {=IF($D36="","",$D36*INDEX(Допущения!$C$25:$G$30,MATCH($C36,Допущения!$B$25:$B$30,0),3))} -> 45158.4 | H36: {=IF($D36="","",$D36*INDEX(Допущения!$C$25:$G$30,MATCH($C36,Допущения!$B$25:$B$30,0),4))} -> 50577.408 | I36: {=IF($D36="","",$D36*INDEX(Допущения!$C$25:$G$30,MATCH($C36,Допущения!$B$25:$B$30,0),5))} -> 56646.697 | J36: =SUM(E36:I36) -> 228702.5 | L36: 0,5 FTE DevOps, монолит не требует выделенного SRE
B37: Поддержка и дежурства 24/7 | C37: ФОТ | D37: 24000 | E37: {=IF($D37="","",$D37*INDEX(Допущения!$C$25:$G$30,MATCH($C37,Допущения!$B$25:$B$30,0),1))} -> 24000 | F37: {=IF($D37="","",$D37*INDEX(Допущения!$C$25:$G$30,MATCH($C37,Допущения!$B$25:$B$30,0),2))} -> 26880 | G37: {=IF($D37="","",$D37*INDEX(Допущения!$C$25:$G$30,MATCH($C37,Допущения!$B$25:$B$30,0),3))} -> 30105.6 | H37: {=IF($D37="","",$D37*INDEX(Допущения!$C$25:$G$30,MATCH($C37,Допущения!$B$25:$B$30,0),4))} -> 33718.272 | I37: {=IF($D37="","",$D37*INDEX(Допущения!$C$25:$G$30,MATCH($C37,Допущения!$B$25:$B$30,0),5))} -> 37764.465 | J37: =SUM(E37:I37) -> 152468.34 | L37: Надбавки за дежурства внутри команды
B38: Архитектура и менеджмент | C38: ФОТ | D38: 120000 | E38: {=IF($D38="","",$D38*INDEX(Допущения!$C$25:$G$30,MATCH($C38,Допущения!$B$25:$B$30,0),1))} -> 120000 | F38: {=IF($D38="","",$D38*INDEX(Допущения!$C$25:$G$30,MATCH($C38,Допущения!$B$25:$B$30,0),2))} -> 134400 | G38: {=IF($D38="","",$D38*INDEX(Допущения!$C$25:$G$30,MATCH($C38,Допущения!$B$25:$B$30,0),3))} -> 150528 | H38: {=IF($D38="","",$D38*INDEX(Допущения!$C$25:$G$30,MATCH($C38,Допущения!$B$25:$B$30,0),4))} -> 168591.36 | I38: {=IF($D38="","",$D38*INDEX(Допущения!$C$25:$G$30,MATCH($C38,Допущения!$B$25:$B$30,0),5))} -> 188822.32 | J38: =SUM(E38:I38) -> 762341.68 | L38: Solution Architect + CTO-функция
C39: фикс | E39: {=IF($D39="","",$D39*INDEX(Допущения!$C$25:$G$30,MATCH($C39,Допущения!$B$25:$B$30,0),1))} | F39: {=IF($D39="","",$D39*INDEX(Допущения!$C$25:$G$30,MATCH($C39,Допущения!$B$25:$B$30,0),2))} | G39: {=IF($D39="","",$D39*INDEX(Допущения!$C$25:$G$30,MATCH($C39,Допущения!$B$25:$B$30,0),3))} | H39: {=IF($D39="","",$D39*INDEX(Допущения!$C$25:$G$30,MATCH($C39,Допущения!$B$25:$B$30,0),4))} | I39: {=IF($D39="","",$D39*INDEX(Допущения!$C$25:$G$30,MATCH($C39,Допущения!$B$25:$B$30,0),5))} | J39: =SUM(E39:I39) -> 0 | L39: Своя статья
B40: Итого по блоку | E40: =SUM(E35:E39) -> 540000 | F40: =SUM(F35:F39) -> 604800 | G40: =SUM(G35:G39) -> 677376 | H40: =SUM(H35:H39) -> 758661.12 | I40: =SUM(I35:I39) -> 849700.45 | J40: =SUM(J35:J39) -> 3430537.6 | K40: =IFERROR(J40/$J$51,0) -> 0.0780905
B42: БЛОК 5. Разовые затраты и комплаенс
B43: Юридический и комплаенс-аудит (NDPR, POPIA, KICA) | C43: фикс | D43: 25000 | E43: {=IF($D43="","",$D43*INDEX(Допущения!$C$25:$G$30,MATCH($C43,Допущения!$B$25:$B$30,0),1))} -> 25000 | F43: 0 | G43: 0 | H43: 0 | I43: 0 | J43: =SUM(E43:I43) -> 25000 | L43: Комплаенс-аудит NDPR/POPIA/KICA, разовый (год 1)
B44: Пентест и аудит безопасности | C44: инфляция | D44: 15000 | E44: {=IF($D44="","",$D44*INDEX(Допущения!$C$25:$G$30,MATCH($C44,Допущения!$B$25:$B$30,0),1))} -> 15000 | F44: {=IF($D44="","",$D44*INDEX(Допущения!$C$25:$G$30,MATCH($C44,Допущения!$B$25:$B$30,0),2))} -> 16200 | G44: {=IF($D44="","",$D44*INDEX(Допущения!$C$25:$G$30,MATCH($C44,Допущения!$B$25:$B$30,0),3))} -> 17496 | H44: {=IF($D44="","",$D44*INDEX(Допущения!$C$25:$G$30,MATCH($C44,Допущения!$B$25:$B$30,0),4))} -> 18895.68 | I44: {=IF($D44="","",$D44*INDEX(Допущения!$C$25:$G$30,MATCH($C44,Допущения!$B$25:$B$30,0),5))} -> 20407.334 | J44: =SUM(E44:I44) -> 87999.014 | L44: Пентест ежегодно
B45: Миграция данных и интеграции при запуске | C45: фикс | D45: 20000 | E45: {=IF($D45="","",$D45*INDEX(Допущения!$C$25:$G$30,MATCH($C45,Допущения!$B$25:$B$30,0),1))} -> 20000 | F45: 0 | G45: 0 | H45: 0 | I45: 0 | J45: =SUM(E45:I45) -> 20000 | L45: Интеграции при запуске, разовые (год 1)
B46: Обучение команды и найм | C46: ФОТ | D46: 10000 | E46: {=IF($D46="","",$D46*INDEX(Допущения!$C$25:$G$30,MATCH($C46,Допущения!$B$25:$B$30,0),1))} -> 10000 | F46: {=IF($D46="","",$D46*INDEX(Допущения!$C$25:$G$30,MATCH($C46,Допущения!$B$25:$B$30,0),2))} -> 11200 | G46: {=IF($D46="","",$D46*INDEX(Допущения!$C$25:$G$30,MATCH($C46,Допущения!$B$25:$B$30,0),3))} -> 12544 | H46: {=IF($D46="","",$D46*INDEX(Допущения!$C$25:$G$30,MATCH($C46,Допущения!$B$25:$B$30,0),4))} -> 14049.28 | I46: {=IF($D46="","",$D46*INDEX(Допущения!$C$25:$G$30,MATCH($C46,Допущения!$B$25:$B$30,0),5))} -> 15735.194 | J46: =SUM(E46:I46) -> 63528.474 | L46: Обучение команды
...

Sheet TCO-B-cto
B2: TCO на 5 лет - Africa Delivery - вариант TCO-B-cto
B3: Заполняем колонки «Драйвер роста» и «База, $/год (Год 1)». Годы 1–5 считаются автоматически.
B5: Статья затрат | C5: Драйвер роста | D5: База, $/год (Год 1) | E5: Год 1 | F5: Год 2 | G5: Год 3 | H5: Год 4 | I5: Год 5 | J5: Итого 5 лет | K5: Доля | L5: Комментарий / источник
B6: БЛОК 1. Облачная инфраструктура (OpEx)
B7: Compute: ноды / контейнеры / serverless | C7: пользователи | D7: 36000 | E7: {=IF($D7="","",$D7*INDEX(Допущения!$C$25:$G$30,MATCH($C7,Допущения!$B$25:$B$30,0),1))} -> 36000 | F7: {=IF($D7="","",$D7*INDEX(Допущения!$C$25:$G$30,MATCH($C7,Допущения!$B$25:$B$30,0),2))} -> 108000 | G7: {=IF($D7="","",$D7*INDEX(Допущения!$C$25:$G$30,MATCH($C7,Допущения!$B$25:$B$30,0),3))} -> 270000 | H7: {=IF($D7="","",$D7*INDEX(Допущения!$C$25:$G$30,MATCH($C7,Допущения!$B$25:$B$30,0),4))} -> 540000 | I7: {=IF($D7="","",$D7*INDEX(Допущения!$C$25:$G$30,MATCH($C7,Допущения!$B$25:$B$30,0),5))} -> 900000 | J7: =SUM(E7:I7) -> 1854000 | L7: 3 кластера K8s (2 региона + on-prem), 9-12 нод (артефакт 5)
B8: Управляемые БД (PostgreSQL, реплики) | C8: фикс | D8: 46000 | E8: {=IF($D8="","",$D8*INDEX(Допущения!$C$25:$G$30,MATCH($C8,Допущения!$B$25:$B$30,0),1))} -> 46000 | F8: {=IF($D8="","",$D8*INDEX(Допущения!$C$25:$G$30,MATCH($C8,Допущения!$B$25:$B$30,0),2))} -> 46000 | G8: {=IF($D8="","",$D8*INDEX(Допущения!$C$25:$G$30,MATCH($C8,Допущения!$B$25:$B$30,0),3))} -> 46000 | H8: {=IF($D8="","",$D8*INDEX(Допущения!$C$25:$G$30,MATCH($C8,Допущения!$B$25:$B$30,0),4))} -> 46000 | I8: {=IF($D8="","",$D8*INDEX(Допущения!$C$25:$G$30,MATCH($C8,Допущения!$B$25:$B$30,0),5))} -> 46000 | J8: =SUM(E8:I8) -> 230000 | L8: Oracle SE2 лицензии+поддержка ~$40k + PostgreSQL для периферии (артефакт 5)
B9: Хранилище объектов и резервные копии | C9: пользователи | D9: 6000 | E9: {=IF($D9="","",$D9*INDEX(Допущения!$C$25:$G$30,MATCH($C9,Допущения!$B$25:$B$30,0),1))} -> 6000 | F9: {=IF($D9="","",$D9*INDEX(Допущения!$C$25:$G$30,MATCH($C9,Допущения!$B$25:$B$30,0),2))} -> 18000 | G9: {=IF($D9="","",$D9*INDEX(Допущения!$C$25:$G$30,MATCH($C9,Допущения!$B$25:$B$30,0),3))} -> 45000 | H9: {=IF($D9="","",$D9*INDEX(Допущения!$C$25:$G$30,MATCH($C9,Допущения!$B$25:$B$30,0),4))} -> 90000 | I9: {=IF($D9="","",$D9*INDEX(Допущения!$C$25:$G$30,MATCH($C9,Допущения!$B$25:$B$30,0),5))} -> 150000 | J9: =SUM(E9:I9) -> 309000 | L9: Хранилище + бэкапы в 2 регионах
B10: CDN и исходящий трафик | C10: пользователи | D10: 15000 | E10: {=IF($D10="","",$D10*INDEX(Допущения!$C$25:$G$30,MATCH($C10,Допущения!$B$25:$B$30,0),1))} -> 15000 | F10: {=IF($D10="","",$D10*INDEX(Допущения!$C$25:$G$30,MATCH($C10,Допущения!$B$25:$B$30,0),2))} -> 45000 | G10: {=IF($D10="","",$D10*INDEX(Допущения!$C$25:$G$30,MATCH($C10,Допущения!$B$25:$B$30,0),3))} -> 112500 | H10: {=IF($D10="","",$D10*INDEX(Допущения!$C$25:$G$30,MATCH($C10,Допущения!$B$25:$B$30,0),4))} -> 225000 | I10: {=IF($D10="","",$D10*INDEX(Допущения!$C$25:$G$30,MATCH($C10,Допущения!$B$25:$B$30,0),5))} -> 375000 | J10: =SUM(E10:I10) -> 772500 | L10: CDN и трафик
B11: Очереди / стриминг (Kafka, SQS) | C11: пользователи | D11: 9600 | E11: {=IF($D11="","",$D11*INDEX(Допущения!$C$25:$G$30,MATCH($C11,Допущения!$B$25:$B$30,0),1))} -> 9600 | F11: {=IF($D11="","",$D11*INDEX(Допущения!$C$25:$G$30,MATCH($C11,Допущения!$B$25:$B$30,0),2))} -> 28800 | G11: {=IF($D11="","",$D11*INDEX(Допущения!$C$25:$G$30,MATCH($C11,Допущения!$B$25:$B$30,0),3))} -> 72000 | H11: {=IF($D11="","",$D11*INDEX(Допущения!$C$25:$G$30,MATCH($C11,Допущения!$B$25:$B$30,0),4))} -> 144000 | I11: {=IF($D11="","",$D11*INDEX(Допущения!$C$25:$G$30,MATCH($C11,Допущения!$B$25:$B$30,0),5))} -> 240000 | J11: =SUM(E11:I11) -> 494400 | L11: Self-hosted Kafka кластер (3 брокера)
B12: Резервный регион / DR | C12: пользователи | D12: 36000 | E12: {=IF($D12="","",$D12*INDEX(Допущения!$C$25:$G$30,MATCH($C12,Допущения!$B$25:$B$30,0),1))} -> 36000 | F12: {=IF($D12="","",$D12*INDEX(Допущения!$C$25:$G$30,MATCH($C12,Допущения!$B$25:$B$30,0),2))} -> 108000 | G12: {=IF($D12="","",$D12*INDEX(Допущения!$C$25:$G$30,MATCH($C12,Допущения!$B$25:$B$30,0),3))} -> 270000 | H12: {=IF($D12="","",$D12*INDEX(Допущения!$C$25:$G$30,MATCH($C12,Допущения!$B$25:$B$30,0),4))} -> 540000 | I12: {=IF($D12="","",$D12*INDEX(Допущения!$C$25:$G$30,MATCH($C12,Допущения!$B$25:$B$30,0),5))} -> 900000 | J12: =SUM(E12:I12) -> 1854000 | L12: Active-active второй регион, RPO=0 (артефакт 5)
B13: Локальное размещение данных (NDPR, Нигерия) | C13: инфляция | D13: 18000 | E13: {=IF($D13="","",$D13*INDEX(Допущения!$C$25:$G$30,MATCH($C13,Допущения!$B$25:$B$30,0),1))} -> 18000 | F13: {=IF($D13="","",$D13*INDEX(Допущения!$C$25:$G$30,MATCH($C13,Допущения!$B$25:$B$30,0),2))} -> 19440 | G13: {=IF($D13="","",$D13*INDEX(Допущения!$C$25:$G$30,MATCH($C13,Допущения!$B$25:$B$30,0),3))} -> 20995.2 | H13: {=IF($D13="","",$D13*INDEX(Допущения!$C$25:$G$30,MATCH($C13,Допущения!$B$25:$B$30,0),4))} -> 22674.816 | I13: {=IF($D13="","",$D13*INDEX(Допущения!$C$25:$G$30,MATCH($C13,Допущения!$B$25:$B$30,0),5))} -> 24488.801 | J13: =SUM(E13:I13) -> 105598.82 | L13: On-prem кластер в Нигерии под ПДн (артефакт 5)
B14: Аналитическая реплика / витрина (OLAP) | C14: пользователи | D14: 9600 | E14: 0 | F14: {=IF($D14="","",$D14*INDEX(Допущения!$C$25:$G$30,MATCH($C14,Допущения!$B$25:$B$30,0),2))} -> 28800 | G14: {=IF($D14="","",$D14*INDEX(Допущения!$C$25:$G$30,MATCH($C14,Допущения!$B$25:$B$30,0),3))} -> 72000 | H14: {=IF($D14="","",$D14*INDEX(Допущения!$C$25:$G$30,MATCH($C14,Допущения!$B$25:$B$30,0),4))} -> 144000 | I14: {=IF($D14="","",$D14*INDEX(Допущения!$C$25:$G$30,MATCH($C14,Допущения!$B$25:$B$30,0),5))} -> 240000 | J14: =SUM(E14:I14) -> 484800 | L14: Аналитический стек (ClickHouse/Druid, CDC из Kafka) - с года 2
B15: Итого по блоку | E15: =SUM(E7:E14) -> 166600 | F15: =SUM(F7:F14) -> 402040 | G15: =SUM(G7:G14) -> 908495.2 | H15: =SUM(H7:H14) -> 1751674.8 | I15: =SUM(I7:I14) -> 2875488.8 | J15: =SUM(J7:J14) -> 6104298.8 | K15: =IFERROR(J15/$J$51,0) -> 0.10801524
B17: БЛОК 2. Лицензии, SaaS и инструменты
B18: Observability (метрики, логи, трейсинг) | C18: пользователи | D18: 6000 | E18: {=IF($D18="","",$D18*INDEX(Допущения!$C$25:$G$30,MATCH($C18,Допущения!$B$25:$B$30,0),1))} -> 6000 | F18: {=IF($D18="","",$D18*INDEX(Допущения!$C$25:$G$30,MATCH($C18,Допущения!$B$25:$B$30,0),2))} -> 18000 | G18: {=IF($D18="","",$D18*INDEX(Допущения!$C$25:$G$30,MATCH($C18,Допущения!$B$25:$B$30,0),3))} -> 45000 | H18: {=IF($D18="","",$D18*INDEX(Допущения!$C$25:$G$30,MATCH($C18,Допущения!$B$25:$B$30,0),4))} -> 90000 | I18: {=IF($D18="","",$D18*INDEX(Допущения!$C$25:$G$30,MATCH($C18,Допущения!$B$25:$B$30,0),5))} -> 150000 | J18: =SUM(E18:I18) -> 309000 | L18: Self-hosted observability стек: Prometheus/Grafana/Jaeger/Loki - compute
B19: CI/CD, репозиторий, артефакты | C19: инфляция | D19: 3600 | E19: {=IF($D19="","",$D19*INDEX(Допущения!$C$25:$G$30,MATCH($C19,Допущения!$B$25:$B$30,0),1))} -> 3600 | F19: {=IF($D19="","",$D19*INDEX(Допущения!$C$25:$G$30,MATCH($C19,Допущения!$B$25:$B$30,0),2))} -> 3888 | G19: {=IF($D19="","",$D19*INDEX(Допущения!$C$25:$G$30,MATCH($C19,Допущения!$B$25:$B$30,0),3))} -> 4199.04 | H19: {=IF($D19="","",$D19*INDEX(Допущения!$C$25:$G$30,MATCH($C19,Допущения!$B$25:$B$30,0),4))} -> 4534.9632 | I19: {=IF($D19="","",$D19*INDEX(Допущения!$C$25:$G$30,MATCH($C19,Допущения!$B$25:$B$30,0),5))} -> 4897.7603 | J19: =SUM(E19:I19) -> 21119.763 | L19: GitHub + ArgoCD self-hosted инфраструктура
B20: Безопасность: WAF, секреты, антифрод | C20: пользователи | D20: 12000 | E20: {=IF($D20="","",$D20*INDEX(Допущения!$C$25:$G$30,MATCH($C20,Допущения!$B$25:$B$30,0),1))} -> 12000 | F20: {=IF($D20="","",$D20*INDEX(Допущения!$C$25:$G$30,MATCH($C20,Допущения!$B$25:$B$30,0),2))} -> 36000 | G20: {=IF($D20="","",$D20*INDEX(Допущения!$C$25:$G$30,MATCH($C20,Допущения!$B$25:$B$30,0),3))} -> 90000 | H20: {=IF($D20="","",$D20*INDEX(Допущения!$C$25:$G$30,MATCH($C20,Допущения!$B$25:$B$30,0),4))} -> 180000 | I20: {=IF($D20="","",$D20*INDEX(Допущения!$C$25:$G$30,MATCH($C20,Допущения!$B$25:$B$30,0),5))} -> 300000 | J20: =SUM(E20:I20) -> 618000 | L20: WAF, секреты, mTLS Istio операционные расходы
B21: WhatsApp Business API (подписка) | C21: инфляция | D21: 3000 | E21: {=IF($D21="","",$D21*INDEX(Допущения!$C$25:$G$30,MATCH($C21,Допущения!$B$25:$B$30,0),1))} -> 3000 | F21: {=IF($D21="","",$D21*INDEX(Допущения!$C$25:$G$30,MATCH($C21,Допущения!$B$25:$B$30,0),2))} -> 3240 | G21: {=IF($D21="","",$D21*INDEX(Допущения!$C$25:$G$30,MATCH($C21,Допущения!$B$25:$B$30,0),3))} -> 3499.2 | H21: {=IF($D21="","",$D21*INDEX(Допущения!$C$25:$G$30,MATCH($C21,Допущения!$B$25:$B$30,0),4))} -> 3779.136 | I21: {=IF($D21="","",$D21*INDEX(Допущения!$C$25:$G$30,MATCH($C21,Допущения!$B$25:$B$30,0),5))} -> 4081.4669 | J21: =SUM(E21:I21) -> 17599.803 | L21: WhatsApp Business API подписка
B22: Прочее ПО и подписки | C22: инфляция | D22: 2400 | E22: {=IF($D22="","",$D22*INDEX(Допущения!$C$25:$G$30,MATCH($C22,Допущения!$B$25:$B$30,0),1))} -> 2400 | F22: {=IF($D22="","",$D22*INDEX(Допущения!$C$25:$G$30,MATCH($C22,Допущения!$B$25:$B$30,0),2))} -> 2592 | G22: {=IF($D22="","",$D22*INDEX(Допущения!$C$25:$G$30,MATCH($C22,Допущения!$B$25:$B$30,0),3))} -> 2799.36 | H22: {=IF($D22="","",$D22*INDEX(Допущения!$C$25:$G$30,MATCH($C22,Допущения!$B$25:$B$30,0),4))} -> 3023.3088 | I22: {=IF($D22="","",$D22*INDEX(Допущения!$C$25:$G$30,MATCH($C22,Допущения!$B$25:$B$30,0),5))} -> 3265.1735 | J22: =SUM(E22:I22) -> 14079.842 | L22: Прочее ПО
C23: фикс | E23: {=IF($D23="","",$D23*INDEX(Допущения!$C$25:$G$30,MATCH($C23,Допущения!$B$25:$B$30,0),1))} | F23: {=IF($D23="","",$D23*INDEX(Допущения!$C$25:$G$30,MATCH($C23,Допущения!$B$25:$B$30,0),2))} | G23: {=IF($D23="","",$D23*INDEX(Допущения!$C$25:$G$30,MATCH($C23,Допущения!$B$25:$B$30,0),3))} | H23: {=IF($D23="","",$D23*INDEX(Допущения!$C$25:$G$30,MATCH($C23,Допущения!$B$25:$B$30,0),4))} | I23: {=IF($D23="","",$D23*INDEX(Допущения!$C$25:$G$30,MATCH($C23,Допущения!$B$25:$B$30,0),5))} | J23: =SUM(E23:I23) -> 0 | L23: Своя статья
B24: Итого по блоку | E24: =SUM(E18:E23) -> 27000 | F24: =SUM(F18:F23) -> 63720 | G24: =SUM(G18:G23) -> 145497.6 | H24: =SUM(H18:H23) -> 281337.41 | I24: =SUM(I18:I23) -> 462244.4 | J24: =SUM(J18:J23) -> 979799.41 | K24: =IFERROR(J24/$J$51,0) -> 0.017337498
B26: БЛОК 3. Транзакционные расходы (Buy / Partner)
B27: Комиссии платёжных провайдеров | C27: GMV | D27: 100800 | E27: {=IF($D27="","",$D27*INDEX(Допущения!$C$25:$G$30,MATCH($C27,Допущения!$B$25:$B$30,0),1))} -> 100800 | F27: {=IF($D27="","",$D27*INDEX(Допущения!$C$25:$G$30,MATCH($C27,Допущения!$B$25:$B$30,0),2))} -> 638400 | G27: {=IF($D27="","",$D27*INDEX(Допущения!$C$25:$G$30,MATCH($C27,Допущения!$B$25:$B$30,0),3))} -> 2240000 | H27: {=IF($D27="","",$D27*INDEX(Допущения!$C$25:$G$30,MATCH($C27,Допущения!$B$25:$B$30,0),4))} -> 4704000 | I27: {=IF($D27="","",$D27*INDEX(Допущения!$C$25:$G$30,MATCH($C27,Допущения!$B$25:$B$30,0),5))} -> 8624000 | J27: =SUM(E27:I27) -> 16307200 | L27: Идентично для всех вариантов
B28: SMS-уведомления | C28: заказы | D28: 16000 | E28: {=IF($D28="","",$D28*INDEX(Допущения!$C$25:$G$30,MATCH($C28,Допущения!$B$25:$B$30,0),1))} -> 16000 | F28: {=IF($D28="","",$D28*INDEX(Допущения!$C$25:$G$30,MATCH($C28,Допущения!$B$25:$B$30,0),2))} -> 96000 | G28: {=IF($D28="","",$D28*INDEX(Допущения!$C$25:$G$30,MATCH($C28,Допущения!$B$25:$B$30,0),3))} -> 320000 | H28: {=IF($D28="","",$D28*INDEX(Допущения!$C$25:$G$30,MATCH($C28,Допущения!$B$25:$B$30,0),4))} -> 640000 | I28: {=IF($D28="","",$D28*INDEX(Допущения!$C$25:$G$30,MATCH($C28,Допущения!$B$25:$B$30,0),5))} -> 1120000 | J28: =SUM(E28:I28) -> 2192000 | L28: Идентично
B29: WhatsApp-сообщения (за диалог) | C29: заказы | D29: 6000 | E29: {=IF($D29="","",$D29*INDEX(Допущения!$C$25:$G$30,MATCH($C29,Допущения!$B$25:$B$30,0),1))} -> 6000 | F29: {=IF($D29="","",$D29*INDEX(Допущения!$C$25:$G$30,MATCH($C29,Допущения!$B$25:$B$30,0),2))} -> 36000 | G29: {=IF($D29="","",$D29*INDEX(Допущения!$C$25:$G$30,MATCH($C29,Допущения!$B$25:$B$30,0),3))} -> 120000 | H29: {=IF($D29="","",$D29*INDEX(Допущения!$C$25:$G$30,MATCH($C29,Допущения!$B$25:$B$30,0),4))} -> 240000 | I29: {=IF($D29="","",$D29*INDEX(Допущения!$C$25:$G$30,MATCH($C29,Допущения!$B$25:$B$30,0),5))} -> 420000 | J29: =SUM(E29:I29) -> 822000 | L29: Идентично
B30: Логистика: интеграции и комиссии партнёров | C30: заказы | D30: 100000 | E30: {=IF($D30="","",$D30*INDEX(Допущения!$C$25:$G$30,MATCH($C30,Допущения!$B$25:$B$30,0),1))} -> 100000 | F30: {=IF($D30="","",$D30*INDEX(Допущения!$C$25:$G$30,MATCH($C30,Допущения!$B$25:$B$30,0),2))} -> 600000 | G30: {=IF($D30="","",$D30*INDEX(Допущения!$C$25:$G$30,MATCH($C30,Допущения!$B$25:$B$30,0),3))} -> 2000000 | H30: {=IF($D30="","",$D30*INDEX(Допущения!$C$25:$G$30,MATCH($C30,Допущения!$B$25:$B$30,0),4))} -> 4000000 | I30: {=IF($D30="","",$D30*INDEX(Допущения!$C$25:$G$30,MATCH($C30,Допущения!$B$25:$B$30,0),5))} -> 7000000 | J30: =SUM(E30:I30) -> 13700000 | L30: Идентично
C31: фикс | E31: {=IF($D31="","",$D31*INDEX(Допущения!$C$25:$G$30,MATCH($C31,Допущения!$B$25:$B$30,0),1))} | F31: {=IF($D31="","",$D31*INDEX(Допущения!$C$25:$G$30,MATCH($C31,Допущения!$B$25:$B$30,0),2))} | G31: {=IF($D31="","",$D31*INDEX(Допущения!$C$25:$G$30,MATCH($C31,Допущения!$B$25:$B$30,0),3))} | H31: {=IF($D31="","",$D31*INDEX(Допущения!$C$25:$G$30,MATCH($C31,Допущения!$B$25:$B$30,0),4))} | I31: {=IF($D31="","",$D31*INDEX(Допущения!$C$25:$G$30,MATCH($C31,Допущения!$B$25:$B$30,0),5))} | J31: =SUM(E31:I31) -> 0 | L31: Своя статья
B32: Итого по блоку | E32: =SUM(E27:E31) -> 222800 | F32: =SUM(F27:F31) -> 1370400 | G32: =SUM(G27:G31) -> 4680000 | H32: =SUM(H27:H31) -> 9584000 | I32: =SUM(I27:I31) -> 17164000 | J32: =SUM(J27:J31) -> 33021200 | K32: =IFERROR(J32/$J$51,0) -> 0.58430836
B34: БЛОК 4. Команда (ФОТ)
B35: Разработка (FTE × годовая ставка) | C35: ФОТ | D35: 840000 | E35: {=IF($D35="","",$D35*INDEX(Допущения!$C$25:$G$30,MATCH($C35,Допущения!$B$25:$B$30,0),1))} -> 840000 | F35: {=IF($D35="","",$D35*INDEX(Допущения!$C$25:$G$30,MATCH($C35,Допущения!$B$25:$B$30,0),2))} -> 940800 | G35: {=IF($D35="","",$D35*INDEX(Допущения!$C$25:$G$30,MATCH($C35,Допущения!$B$25:$B$30,0),3))} -> 1053696 | H35: {=IF($D35="","",$D35*INDEX(Допущения!$C$25:$G$30,MATCH($C35,Допущения!$B$25:$B$30,0),4))} -> 1180139.5 | I35: {=IF($D35="","",$D35*INDEX(Допущения!$C$25:$G$30,MATCH($C35,Допущения!$B$25:$B$30,0),5))} -> 1321756.3 | J35: =SUM(E35:I35) -> 5336391.8 | L35: 12 разработчиков x $70k - наем вопреки заморозке (артефакты 5 vs 6)
B36: DevOps / SRE | C36: ФОТ | D36: 240000 | E36: {=IF($D36="","",$D36*INDEX(Допущения!$C$25:$G$30,MATCH($C36,Допущения!$B$25:$B$30,0),1))} -> 240000 | F36: {=IF($D36="","",$D36*INDEX(Допущения!$C$25:$G$30,MATCH($C36,Допущения!$B$25:$B$30,0),2))} -> 268800 | G36: {=IF($D36="","",$D36*INDEX(Допущения!$C$25:$G$30,MATCH($C36,Допущения!$B$25:$B$30,0),3))} -> 301056 | H36: {=IF($D36="","",$D36*INDEX(Допущения!$C$25:$G$30,MATCH($C36,Допущения!$B$25:$B$30,0),4))} -> 337182.72 | I36: {=IF($D36="","",$D36*INDEX(Допущения!$C$25:$G$30,MATCH($C36,Допущения!$B$25:$B$30,0),5))} -> 377644.65 | J36: =SUM(E36:I36) -> 1524683.4 | L36: 3 SRE x $80k: 3 кластера, Istio, Kafka, GitOps
B37: Поддержка и дежурства 24/7 | C37: ФОТ | D37: 96000 | E37: {=IF($D37="","",$D37*INDEX(Допущения!$C$25:$G$30,MATCH($C37,Допущения!$B$25:$B$30,0),1))} -> 96000 | F37: {=IF($D37="","",$D37*INDEX(Допущения!$C$25:$G$30,MATCH($C37,Допущения!$B$25:$B$30,0),2))} -> 107520 | G37: {=IF($D37="","",$D37*INDEX(Допущения!$C$25:$G$30,MATCH($C37,Допущения!$B$25:$B$30,0),3))} -> 120422.4 | H37: {=IF($D37="","",$D37*INDEX(Допущения!$C$25:$G$30,MATCH($C37,Допущения!$B$25:$B$30,0),4))} -> 134873.09 | I37: {=IF($D37="","",$D37*INDEX(Допущения!$C$25:$G$30,MATCH($C37,Допущения!$B$25:$B$30,0),5))} -> 151057.86 | J37: =SUM(E37:I37) -> 609873.35 | L37: Дежурства 24/7 под 99,99%
B38: Архитектура и менеджмент | C38: ФОТ | D38: 150000 | E38: {=IF($D38="","",$D38*INDEX(Допущения!$C$25:$G$30,MATCH($C38,Допущения!$B$25:$B$30,0),1))} -> 150000 | F38: {=IF($D38="","",$D38*INDEX(Допущения!$C$25:$G$30,MATCH($C38,Допущения!$B$25:$B$30,0),2))} -> 168000 | G38: {=IF($D38="","",$D38*INDEX(Допущения!$C$25:$G$30,MATCH($C38,Допущения!$B$25:$B$30,0),3))} -> 188160 | H38: {=IF($D38="","",$D38*INDEX(Допущения!$C$25:$G$30,MATCH($C38,Допущения!$B$25:$B$30,0),4))} -> 210739.2 | I38: {=IF($D38="","",$D38*INDEX(Допущения!$C$25:$G$30,MATCH($C38,Допущения!$B$25:$B$30,0),5))} -> 236027.9 | J38: =SUM(E38:I38) -> 952927.1 | L38: SA + CTO-функция + PM
C39: фикс | E39: {=IF($D39="","",$D39*INDEX(Допущения!$C$25:$G$30,MATCH($C39,Допущения!$B$25:$B$30,0),1))} | F39: {=IF($D39="","",$D39*INDEX(Допущения!$C$25:$G$30,MATCH($C39,Допущения!$B$25:$B$30,0),2))} | G39: {=IF($D39="","",$D39*INDEX(Допущения!$C$25:$G$30,MATCH($C39,Допущения!$B$25:$B$30,0),3))} | H39: {=IF($D39="","",$D39*INDEX(Допущения!$C$25:$G$30,MATCH($C39,Допущения!$B$25:$B$30,0),4))} | I39: {=IF($D39="","",$D39*INDEX(Допущения!$C$25:$G$30,MATCH($C39,Допущения!$B$25:$B$30,0),5))} | J39: =SUM(E39:I39) -> 0 | L39: Своя статья
B40: Итого по блоку | E40: =SUM(E35:E39) -> 1326000 | F40: =SUM(F35:F39) -> 1485120 | G40: =SUM(G35:G39) -> 1663334.4 | H40: =SUM(H35:H39) -> 1862934.5 | I40: =SUM(I35:I39) -> 2086486.7 | J40: =SUM(J35:J39) -> 8423875.6 | K40: =IFERROR(J40/$J$51,0) -> 0.14906003
B42: БЛОК 5. Разовые затраты и комплаенс
B43: Юридический и комплаенс-аудит (NDPR, POPIA, KICA) | C43: фикс | D43: 25000 | E43: {=IF($D43="","",$D43*INDEX(Допущения!$C$25:$G$30,MATCH($C43,Допущения!$B$25:$B$30,0),1))} -> 25000 | F43: 0 | G43: 0 | H43: 0 | I43: 0 | J43: =SUM(E43:I43) -> 25000 | L43: Комплаенс-аудит, разовый (год 1)
B44: Пентест и аудит безопасности | C44: инфляция | D44: 25000 | E44: {=IF($D44="","",$D44*INDEX(Допущения!$C$25:$G$30,MATCH($C44,Допущения!$B$25:$B$30,0),1))} -> 25000 | F44: {=IF($D44="","",$D44*INDEX(Допущения!$C$25:$G$30,MATCH($C44,Допущения!$B$25:$B$30,0),2))} -> 27000 | G44: {=IF($D44="","",$D44*INDEX(Допущения!$C$25:$G$30,MATCH($C44,Допущения!$B$25:$B$30,0),3))} -> 29160 | H44: {=IF($D44="","",$D44*INDEX(Допущения!$C$25:$G$30,MATCH($C44,Допущения!$B$25:$B$30,0),4))} -> 31492.8 | I44: {=IF($D44="","",$D44*INDEX(Допущения!$C$25:$G$30,MATCH($C44,Допущения!$B$25:$B$30,0),5))} -> 34012.224 | J44: =SUM(E44:I44) -> 146665.02 | L44: Пентест + аудит 40-50 сервисов
B45: Миграция данных и интеграции при запуске | C45: фикс | D45: 60000 | E45: {=IF($D45="","",$D45*INDEX(Допущения!$C$25:$G$30,MATCH($C45,Допущения!$B$25:$B$30,0),1))} -> 60000 | F45: 0 | G45: 0 | H45: 0 | I45: 0 | J45: =SUM(E45:I45) -> 60000 | L45: Интеграции + построение платформы, разовые (год 1)
B46: Обучение команды и найм | C46: ФОТ | D46: 60000 | E46: {=IF($D46="","",$D46*INDEX(Допущения!$C$25:$G$30,MATCH($C46,Допущения!$B$25:$B$30,0),1))} -> 60000 | F46: {=IF($D46="","",$D46*INDEX(Допущения!$C$25:$G$30,MATCH($C46,Допущения!$B$25:$B$30,0),2))} -> 67200 | G46: {=IF($D46="","",$D46*INDEX(Допущения!$C$25:$G$30,MATCH($C46,Допущения!$B$25:$B$30,0),3))} -> 75264 | H46: {=IF($D46="","",$D46*INDEX(Допущения!$C$25:$G$30,MATCH($C46,Допущения!$B$25:$B$30,0),4))} -> 84295.68 | I46: {=IF($D46="","",$D46*INDEX(Допущения!$C$25:$G$30,MATCH($C46,Допущения!$B$25:$B$30,0),5))} -> 94411.162 | J46: =SUM(E46:I46) -> 381170.84 | L46: Найм и онбординг 12+ человек на рынке с дефицитом Go
...

Sheet TCO-C1-macro
B2: TCO на 5 лет - Africa Delivery - вариант TCO-C1-macro
B3: Заполняем колонки «Драйвер роста» и «База, $/год (Год 1)». Годы 1–5 считаются автоматически.
B5: Статья затрат | C5: Драйвер роста | D5: База, $/год (Год 1) | E5: Год 1 | F5: Год 2 | G5: Год 3 | H5: Год 4 | I5: Год 5 | J5: Итого 5 лет | K5: Доля | L5: Комментарий / источник
B6: БЛОК 1. Облачная инфраструктура (OpEx)
B7: Compute: ноды / контейнеры / serverless | C7: пользователи | D7: 14400 | E7: {=IF($D7="","",$D7*INDEX(Допущения!$C$25:$G$30,MATCH($C7,Допущения!$B$25:$B$30,0),1))} -> 14400 | F7: {=IF($D7="","",$D7*INDEX(Допущения!$C$25:$G$30,MATCH($C7,Допущения!$B$25:$B$30,0),2))} -> 43200 | G7: {=IF($D7="","",$D7*INDEX(Допущения!$C$25:$G$30,MATCH($C7,Допущения!$B$25:$B$30,0),3))} -> 108000 | H7: {=IF($D7="","",$D7*INDEX(Допущения!$C$25:$G$30,MATCH($C7,Допущения!$B$25:$B$30,0),4))} -> 216000 | I7: {=IF($D7="","",$D7*INDEX(Допущения!$C$25:$G$30,MATCH($C7,Допущения!$B$25:$B$30,0),5))} -> 360000 | J7: =SUM(E7:I7) -> 741600 | L7: 1 managed K8s кластер, 6-8 нод, 5-7 сервисов
B8: Управляемые БД (PostgreSQL, реплики) | C8: пользователи | D8: 7200 | E8: {=IF($D8="","",$D8*INDEX(Допущения!$C$25:$G$30,MATCH($C8,Допущения!$B$25:$B$30,0),1))} -> 7200 | F8: {=IF($D8="","",$D8*INDEX(Допущения!$C$25:$G$30,MATCH($C8,Допущения!$B$25:$B$30,0),2))} -> 21600 | G8: {=IF($D8="","",$D8*INDEX(Допущения!$C$25:$G$30,MATCH($C8,Допущения!$B$25:$B$30,0),3))} -> 54000 | H8: {=IF($D8="","",$D8*INDEX(Допущения!$C$25:$G$30,MATCH($C8,Допущения!$B$25:$B$30,0),4))} -> 108000 | I8: {=IF($D8="","",$D8*INDEX(Допущения!$C$25:$G$30,MATCH($C8,Допущения!$B$25:$B$30,0),5))} -> 180000 | J8: =SUM(E8:I8) -> 370800 | L8: Managed PostgreSQL + реплики, по БД на сервис-кандидат
B9: Хранилище объектов и резервные копии | C9: пользователи | D9: 2400 | E9: {=IF($D9="","",$D9*INDEX(Допущения!$C$25:$G$30,MATCH($C9,Допущения!$B$25:$B$30,0),1))} -> 2400 | F9: {=IF($D9="","",$D9*INDEX(Допущения!$C$25:$G$30,MATCH($C9,Допущения!$B$25:$B$30,0),2))} -> 7200 | G9: {=IF($D9="","",$D9*INDEX(Допущения!$C$25:$G$30,MATCH($C9,Допущения!$B$25:$B$30,0),3))} -> 18000 | H9: {=IF($D9="","",$D9*INDEX(Допущения!$C$25:$G$30,MATCH($C9,Допущения!$B$25:$B$30,0),4))} -> 36000 | I9: {=IF($D9="","",$D9*INDEX(Допущения!$C$25:$G$30,MATCH($C9,Допущения!$B$25:$B$30,0),5))} -> 60000 | J9: =SUM(E9:I9) -> 123600 | L9: Хранилище + бэкапы
B10: CDN и исходящий трафик | C10: пользователи | D10: 4800 | E10: {=IF($D10="","",$D10*INDEX(Допущения!$C$25:$G$30,MATCH($C10,Допущения!$B$25:$B$30,0),1))} -> 4800 | F10: {=IF($D10="","",$D10*INDEX(Допущения!$C$25:$G$30,MATCH($C10,Допущения!$B$25:$B$30,0),2))} -> 14400 | G10: {=IF($D10="","",$D10*INDEX(Допущения!$C$25:$G$30,MATCH($C10,Допущения!$B$25:$B$30,0),3))} -> 36000 | H10: {=IF($D10="","",$D10*INDEX(Допущения!$C$25:$G$30,MATCH($C10,Допущения!$B$25:$B$30,0),4))} -> 72000 | I10: {=IF($D10="","",$D10*INDEX(Допущения!$C$25:$G$30,MATCH($C10,Допущения!$B$25:$B$30,0),5))} -> 120000 | J10: =SUM(E10:I10) -> 247200 | L10: CDN и трафик
B11: Очереди / стриминг (Kafka, SQS) | C11: пользователи | D11: 2400 | E11: {=IF($D11="","",$D11*INDEX(Допущения!$C$25:$G$30,MATCH($C11,Допущения!$B$25:$B$30,0),1))} -> 2400 | F11: {=IF($D11="","",$D11*INDEX(Допущения!$C$25:$G$30,MATCH($C11,Допущения!$B$25:$B$30,0),2))} -> 7200 | G11: {=IF($D11="","",$D11*INDEX(Допущения!$C$25:$G$30,MATCH($C11,Допущения!$B$25:$B$30,0),3))} -> 18000 | H11: {=IF($D11="","",$D11*INDEX(Допущения!$C$25:$G$30,MATCH($C11,Допущения!$B$25:$B$30,0),4))} -> 36000 | I11: {=IF($D11="","",$D11*INDEX(Допущения!$C$25:$G$30,MATCH($C11,Допущения!$B$25:$B$30,0),5))} -> 60000 | J11: =SUM(E11:I11) -> 123600 | L11: Managed очередь между сервисами
B12: Резервный регион / DR | C12: пользователи | D12: 6000 | E12: {=IF($D12="","",$D12*INDEX(Допущения!$C$25:$G$30,MATCH($C12,Допущения!$B$25:$B$30,0),1))} -> 6000 | F12: {=IF($D12="","",$D12*INDEX(Допущения!$C$25:$G$30,MATCH($C12,Допущения!$B$25:$B$30,0),2))} -> 18000 | G12: {=IF($D12="","",$D12*INDEX(Допущения!$C$25:$G$30,MATCH($C12,Допущения!$B$25:$B$30,0),3))} -> 45000 | H12: {=IF($D12="","",$D12*INDEX(Допущения!$C$25:$G$30,MATCH($C12,Допущения!$B$25:$B$30,0),4))} -> 90000 | I12: {=IF($D12="","",$D12*INDEX(Допущения!$C$25:$G$30,MATCH($C12,Допущения!$B$25:$B$30,0),5))} -> 150000 | J12: =SUM(E12:I12) -> 309000 | L12: реплики + автоматический failover БД
B13: Локальное размещение данных (NDPR, Нигерия) | C13: инфляция | D13: 9600 | E13: {=IF($D13="","",$D13*INDEX(Допущения!$C$25:$G$30,MATCH($C13,Допущения!$B$25:$B$30,0),1))} -> 9600 | F13: {=IF($D13="","",$D13*INDEX(Допущения!$C$25:$G$30,MATCH($C13,Допущения!$B$25:$B$30,0),2))} -> 10368 | G13: {=IF($D13="","",$D13*INDEX(Допущения!$C$25:$G$30,MATCH($C13,Допущения!$B$25:$B$30,0),3))} -> 11197.44 | H13: {=IF($D13="","",$D13*INDEX(Допущения!$C$25:$G$30,MATCH($C13,Допущения!$B$25:$B$30,0),4))} -> 12093.235 | I13: {=IF($D13="","",$D13*INDEX(Допущения!$C$25:$G$30,MATCH($C13,Допущения!$B$25:$B$30,0),5))} -> 13060.694 | J13: =SUM(E13:I13) -> 56319.369 | L13: Локальный провайдер в Нигерии под ПДн (артефакт 3)
B14: Аналитическая реплика / витрина (OLAP) | C14: пользователи | D14: 2400 | E14: 0 | F14: {=IF($D14="","",$D14*INDEX(Допущения!$C$25:$G$30,MATCH($C14,Допущения!$B$25:$B$30,0),2))} -> 7200 | G14: {=IF($D14="","",$D14*INDEX(Допущения!$C$25:$G$30,MATCH($C14,Допущения!$B$25:$B$30,0),3))} -> 18000 | H14: {=IF($D14="","",$D14*INDEX(Допущения!$C$25:$G$30,MATCH($C14,Допущения!$B$25:$B$30,0),4))} -> 36000 | I14: {=IF($D14="","",$D14*INDEX(Допущения!$C$25:$G$30,MATCH($C14,Допущения!$B$25:$B$30,0),5))} -> 60000 | J14: =SUM(E14:I14) -> 121200 | L14: Аналитическая реплика/витрина OLAP - со второго года
B15: Итого по блоку | E15: =SUM(E7:E14) -> 46800 | F15: =SUM(F7:F14) -> 129168 | G15: =SUM(G7:G14) -> 308197.44 | H15: =SUM(H7:H14) -> 606093.24 | I15: =SUM(I7:I14) -> 1003060.7 | J15: =SUM(J7:J14) -> 2093319.4 | K15: =IFERROR(J15/$J$51,0) -> 0.045002464
B17: БЛОК 2. Лицензии, SaaS и инструменты
B18: Observability (метрики, логи, трейсинг) | C18: пользователи | D18: 6000 | E18: {=IF($D18="","",$D18*INDEX(Допущения!$C$25:$G$30,MATCH($C18,Допущения!$B$25:$B$30,0),1))} -> 6000 | F18: {=IF($D18="","",$D18*INDEX(Допущения!$C$25:$G$30,MATCH($C18,Допущения!$B$25:$B$30,0),2))} -> 18000 | G18: {=IF($D18="","",$D18*INDEX(Допущения!$C$25:$G$30,MATCH($C18,Допущения!$B$25:$B$30,0),3))} -> 45000 | H18: {=IF($D18="","",$D18*INDEX(Допущения!$C$25:$G$30,MATCH($C18,Допущения!$B$25:$B$30,0),4))} -> 90000 | I18: {=IF($D18="","",$D18*INDEX(Допущения!$C$25:$G$30,MATCH($C18,Допущения!$B$25:$B$30,0),5))} -> 150000 | J18: =SUM(E18:I18) -> 309000 | L18: Observability на 5-7 сервисов: managed + OSS
B19: CI/CD, репозиторий, артефакты | C19: инфляция | D19: 3000 | E19: {=IF($D19="","",$D19*INDEX(Допущения!$C$25:$G$30,MATCH($C19,Допущения!$B$25:$B$30,0),1))} -> 3000 | F19: {=IF($D19="","",$D19*INDEX(Допущения!$C$25:$G$30,MATCH($C19,Допущения!$B$25:$B$30,0),2))} -> 3240 | G19: {=IF($D19="","",$D19*INDEX(Допущения!$C$25:$G$30,MATCH($C19,Допущения!$B$25:$B$30,0),3))} -> 3499.2 | H19: {=IF($D19="","",$D19*INDEX(Допущения!$C$25:$G$30,MATCH($C19,Допущения!$B$25:$B$30,0),4))} -> 3779.136 | I19: {=IF($D19="","",$D19*INDEX(Допущения!$C$25:$G$30,MATCH($C19,Допущения!$B$25:$B$30,0),5))} -> 4081.4669 | J19: =SUM(E19:I19) -> 17599.803 | L19: GitHub Team, 7 пайплайнов
B20: Безопасность: WAF, секреты, антифрод | C20: пользователи | D20: 4800 | E20: {=IF($D20="","",$D20*INDEX(Допущения!$C$25:$G$30,MATCH($C20,Допущения!$B$25:$B$30,0),1))} -> 4800 | F20: {=IF($D20="","",$D20*INDEX(Допущения!$C$25:$G$30,MATCH($C20,Допущения!$B$25:$B$30,0),2))} -> 14400 | G20: {=IF($D20="","",$D20*INDEX(Допущения!$C$25:$G$30,MATCH($C20,Допущения!$B$25:$B$30,0),3))} -> 36000 | H20: {=IF($D20="","",$D20*INDEX(Допущения!$C$25:$G$30,MATCH($C20,Допущения!$B$25:$B$30,0),4))} -> 72000 | I20: {=IF($D20="","",$D20*INDEX(Допущения!$C$25:$G$30,MATCH($C20,Допущения!$B$25:$B$30,0),5))} -> 120000 | J20: =SUM(E20:I20) -> 247200 | L20: WAF, секреты
B21: WhatsApp Business API (подписка) | C21: инфляция | D21: 3000 | E21: {=IF($D21="","",$D21*INDEX(Допущения!$C$25:$G$30,MATCH($C21,Допущения!$B$25:$B$30,0),1))} -> 3000 | F21: {=IF($D21="","",$D21*INDEX(Допущения!$C$25:$G$30,MATCH($C21,Допущения!$B$25:$B$30,0),2))} -> 3240 | G21: {=IF($D21="","",$D21*INDEX(Допущения!$C$25:$G$30,MATCH($C21,Допущения!$B$25:$B$30,0),3))} -> 3499.2 | H21: {=IF($D21="","",$D21*INDEX(Допущения!$C$25:$G$30,MATCH($C21,Допущения!$B$25:$B$30,0),4))} -> 3779.136 | I21: {=IF($D21="","",$D21*INDEX(Допущения!$C$25:$G$30,MATCH($C21,Допущения!$B$25:$B$30,0),5))} -> 4081.4669 | J21: =SUM(E21:I21) -> 17599.803 | L21: WhatsApp Business API
B22: Прочее ПО и подписки | C22: инфляция | D22: 2400 | E22: {=IF($D22="","",$D22*INDEX(Допущения!$C$25:$G$30,MATCH($C22,Допущения!$B$25:$B$30,0),1))} -> 2400 | F22: {=IF($D22="","",$D22*INDEX(Допущения!$C$25:$G$30,MATCH($C22,Допущения!$B$25:$B$30,0),2))} -> 2592 | G22: {=IF($D22="","",$D22*INDEX(Допущения!$C$25:$G$30,MATCH($C22,Допущения!$B$25:$B$30,0),3))} -> 2799.36 | H22: {=IF($D22="","",$D22*INDEX(Допущения!$C$25:$G$30,MATCH($C22,Допущения!$B$25:$B$30,0),4))} -> 3023.3088 | I22: {=IF($D22="","",$D22*INDEX(Допущения!$C$25:$G$30,MATCH($C22,Допущения!$B$25:$B$30,0),5))} -> 3265.1735 | J22: =SUM(E22:I22) -> 14079.842 | L22: Прочее ПО
C23: фикс | E23: {=IF($D23="","",$D23*INDEX(Допущения!$C$25:$G$30,MATCH($C23,Допущения!$B$25:$B$30,0),1))} | F23: {=IF($D23="","",$D23*INDEX(Допущения!$C$25:$G$30,MATCH($C23,Допущения!$B$25:$B$30,0),2))} | G23: {=IF($D23="","",$D23*INDEX(Допущения!$C$25:$G$30,MATCH($C23,Допущения!$B$25:$B$30,0),3))} | H23: {=IF($D23="","",$D23*INDEX(Допущения!$C$25:$G$30,MATCH($C23,Допущения!$B$25:$B$30,0),4))} | I23: {=IF($D23="","",$D23*INDEX(Допущения!$C$25:$G$30,MATCH($C23,Допущения!$B$25:$B$30,0),5))} | J23: =SUM(E23:I23) -> 0 | L23: Своя статья
B24: Итого по блоку | E24: =SUM(E18:E23) -> 19200 | F24: =SUM(F18:F23) -> 41472 | G24: =SUM(G18:G23) -> 90797.76 | H24: =SUM(H18:H23) -> 172581.58 | I24: =SUM(I18:I23) -> 281428.11 | J24: =SUM(J18:J23) -> 605479.45 | K24: =IFERROR(J24/$J$51,0) -> 0.013016679
B26: БЛОК 3. Транзакционные расходы (Buy / Partner)
B27: Комиссии платёжных провайдеров | C27: GMV | D27: 100800 | E27: {=IF($D27="","",$D27*INDEX(Допущения!$C$25:$G$30,MATCH($C27,Допущения!$B$25:$B$30,0),1))} -> 100800 | F27: {=IF($D27="","",$D27*INDEX(Допущения!$C$25:$G$30,MATCH($C27,Допущения!$B$25:$B$30,0),2))} -> 638400 | G27: {=IF($D27="","",$D27*INDEX(Допущения!$C$25:$G$30,MATCH($C27,Допущения!$B$25:$B$30,0),3))} -> 2240000 | H27: {=IF($D27="","",$D27*INDEX(Допущения!$C$25:$G$30,MATCH($C27,Допущения!$B$25:$B$30,0),4))} -> 4704000 | I27: {=IF($D27="","",$D27*INDEX(Допущения!$C$25:$G$30,MATCH($C27,Допущения!$B$25:$B$30,0),5))} -> 8624000 | J27: =SUM(E27:I27) -> 16307200 | L27: Идентично для всех вариантов
B28: SMS-уведомления | C28: заказы | D28: 16000 | E28: {=IF($D28="","",$D28*INDEX(Допущения!$C$25:$G$30,MATCH($C28,Допущения!$B$25:$B$30,0),1))} -> 16000 | F28: {=IF($D28="","",$D28*INDEX(Допущения!$C$25:$G$30,MATCH($C28,Допущения!$B$25:$B$30,0),2))} -> 96000 | G28: {=IF($D28="","",$D28*INDEX(Допущения!$C$25:$G$30,MATCH($C28,Допущения!$B$25:$B$30,0),3))} -> 320000 | H28: {=IF($D28="","",$D28*INDEX(Допущения!$C$25:$G$30,MATCH($C28,Допущения!$B$25:$B$30,0),4))} -> 640000 | I28: {=IF($D28="","",$D28*INDEX(Допущения!$C$25:$G$30,MATCH($C28,Допущения!$B$25:$B$30,0),5))} -> 1120000 | J28: =SUM(E28:I28) -> 2192000 | L28: Идентично
B29: WhatsApp-сообщения (за диалог) | C29: заказы | D29: 6000 | E29: {=IF($D29="","",$D29*INDEX(Допущения!$C$25:$G$30,MATCH($C29,Допущения!$B$25:$B$30,0),1))} -> 6000 | F29: {=IF($D29="","",$D29*INDEX(Допущения!$C$25:$G$30,MATCH($C29,Допущения!$B$25:$B$30,0),2))} -> 36000 | G29: {=IF($D29="","",$D29*INDEX(Допущения!$C$25:$G$30,MATCH($C29,Допущения!$B$25:$B$30,0),3))} -> 120000 | H29: {=IF($D29="","",$D29*INDEX(Допущения!$C$25:$G$30,MATCH($C29,Допущения!$B$25:$B$30,0),4))} -> 240000 | I29: {=IF($D29="","",$D29*INDEX(Допущения!$C$25:$G$30,MATCH($C29,Допущения!$B$25:$B$30,0),5))} -> 420000 | J29: =SUM(E29:I29) -> 822000 | L29: Идентично
B30: Логистика: интеграции и комиссии партнёров | C30: заказы | D30: 100000 | E30: {=IF($D30="","",$D30*INDEX(Допущения!$C$25:$G$30,MATCH($C30,Допущения!$B$25:$B$30,0),1))} -> 100000 | F30: {=IF($D30="","",$D30*INDEX(Допущения!$C$25:$G$30,MATCH($C30,Допущения!$B$25:$B$30,0),2))} -> 600000 | G30: {=IF($D30="","",$D30*INDEX(Допущения!$C$25:$G$30,MATCH($C30,Допущения!$B$25:$B$30,0),3))} -> 2000000 | H30: {=IF($D30="","",$D30*INDEX(Допущения!$C$25:$G$30,MATCH($C30,Допущения!$B$25:$B$30,0),4))} -> 4000000 | I30: {=IF($D30="","",$D30*INDEX(Допущения!$C$25:$G$30,MATCH($C30,Допущения!$B$25:$B$30,0),5))} -> 7000000 | J30: =SUM(E30:I30) -> 13700000 | L30: Идентично
C31: фикс | E31: {=IF($D31="","",$D31*INDEX(Допущения!$C$25:$G$30,MATCH($C31,Допущения!$B$25:$B$30,0),1))} | F31: {=IF($D31="","",$D31*INDEX(Допущения!$C$25:$G$30,MATCH($C31,Допущения!$B$25:$B$30,0),2))} | G31: {=IF($D31="","",$D31*INDEX(Допущения!$C$25:$G$30,MATCH($C31,Допущения!$B$25:$B$30,0),3))} | H31: {=IF($D31="","",$D31*INDEX(Допущения!$C$25:$G$30,MATCH($C31,Допущения!$B$25:$B$30,0),4))} | I31: {=IF($D31="","",$D31*INDEX(Допущения!$C$25:$G$30,MATCH($C31,Допущения!$B$25:$B$30,0),5))} | J31: =SUM(E31:I31) -> 0 | L31: Своя статья
B32: Итого по блоку | E32: =SUM(E27:E31) -> 222800 | F32: =SUM(F27:F31) -> 1370400 | G32: =SUM(G27:G31) -> 4680000 | H32: =SUM(H27:H31) -> 9584000 | I32: =SUM(I27:I31) -> 17164000 | J32: =SUM(J27:J31) -> 33021200 | K32: =IFERROR(J32/$J$51,0) -> 0.70989425
B34: БЛОК 4. Команда (ФОТ)
B35: Разработка (FTE × годовая ставка) | C35: ФОТ | D35: 455000 | E35: {=IF($D35="","",$D35*INDEX(Допущения!$C$25:$G$30,MATCH($C35,Допущения!$B$25:$B$30,0),1))} -> 455000 | F35: {=IF($D35="","",$D35*INDEX(Допущения!$C$25:$G$30,MATCH($C35,Допущения!$B$25:$B$30,0),2))} -> 509600 | G35: {=IF($D35="","",$D35*INDEX(Допущения!$C$25:$G$30,MATCH($C35,Допущения!$B$25:$B$30,0),3))} -> 570752 | H35: {=IF($D35="","",$D35*INDEX(Допущения!$C$25:$G$30,MATCH($C35,Допущения!$B$25:$B$30,0),4))} -> 639242.24 | I35: {=IF($D35="","",$D35*INDEX(Допущения!$C$25:$G$30,MATCH($C35,Допущения!$B$25:$B$30,0),5))} -> 715951.31 | J35: =SUM(E35:I35) -> 2890545.5 | L35: 7 разработчиков x $65k - +1 к штату CFO, требует согласования
B36: DevOps / SRE | C36: ФОТ | D36: 80000 | E36: {=IF($D36="","",$D36*INDEX(Допущения!$C$25:$G$30,MATCH($C36,Допущения!$B$25:$B$30,0),1))} -> 80000 | F36: {=IF($D36="","",$D36*INDEX(Допущения!$C$25:$G$30,MATCH($C36,Допущения!$B$25:$B$30,0),2))} -> 89600 | G36: {=IF($D36="","",$D36*INDEX(Допущения!$C$25:$G$30,MATCH($C36,Допущения!$B$25:$B$30,0),3))} -> 100352 | H36: {=IF($D36="","",$D36*INDEX(Допущения!$C$25:$G$30,MATCH($C36,Допущения!$B$25:$B$30,0),4))} -> 112394.24 | I36: {=IF($D36="","",$D36*INDEX(Допущения!$C$25:$G$30,MATCH($C36,Допущения!$B$25:$B$30,0),5))} -> 125881.55 | J36: =SUM(E36:I36) -> 508227.79 | L36: 1 SRE x $80k
